<?xml version='1.0' encoding='utf-8'?>
<robot name="galbot_one_arm">
  <link name="base_link">
    <inertial>
      <origin xyz="0.00053759 -0.0064563 0.047133" rpy="0 0 0" />
      <mass value="0.42402" />
      <inertia ixx="0.00032797" ixy="-3.2021E-07" ixz="7.8672E-06" iyy="0.00030712" iyz="1.1227E-06" izz="0.0003995" />
    </inertial>
    <visual>
      <origin xyz="0 0 0" rpy="0 0 0" />
      <geometry>
        <mesh filename="meshes/base_link.stl" />
      </geometry>
      <material name="">
        <color rgba="0.75294 0.75294 0.75294 1" />
      </material>
    </visual>
    <collision>
      <origin xyz="0 0 0" rpy="0 0 0" />
      <geometry>
        <mesh filename="meshes/base_link.stl" />
      </geometry>
    </collision>
  </link>
  <link name="link1">
    <inertial>
      <origin xyz="-0.00053387 0.0013806 -0.0079585" rpy="0 0 0" />
      <mass value="0.41938" />
      <inertia ixx="0.00033462" ixy="-7.7588E-06" ixz="-6.7213E-07" iyy="0.00037323" iyz="2.132E-05" izz="0.00032753" />
    </inertial>
    <visual>
      <origin xyz="0 0 0" rpy="0 0 0" />
      <geometry>
        <mesh filename="meshes/link1.stl" />
      </geometry>
      <material name="">
        <color rgba="0.75294 0.75294 0.75294 1" />
      </material>
    </visual>
    <collision>
      <origin xyz="0 0 0" rpy="0 0 0" />
      <geometry>
        <mesh filename="meshes/link1.stl" />
      </geometry>
    </collision>
  </link>
  <joint name="joint1" type="revolute">
    <origin xyz="0 0 0.16" rpy="0 0 1.5708" />
    <parent link="base_link" />
    <child link="link1" />
    <axis xyz="0 0 1" />
    <limit lower="-2.94" upper="2.94" effort="60" velocity="1.5" />
  </joint>
  <link name="link2">
    <inertial>
      <origin xyz="5.6769E-05 0.12878 0.0099789" rpy="0 0 0" />
      <mass value="0.35274" />
      <inertia ixx="0.00041467" ixy="6.6686E-07" ixz="2.7602E-07" iyy="0.00023745" iyz="4.3582E-05" izz="0.00041598" />
    </inertial>
    <visual>
      <origin xyz="0 0 0" rpy="0 0 0" />
      <geometry>
        <mesh filename="meshes/link2.stl" />
      </geometry>
      <material name="">
        <color rgba="0.75294 0.75294 0.75294 1" />
      </material>
    </visual>
    <collision>
      <origin xyz="0 0 0" rpy="0 0 0" />
      <geometry>
        <mesh filename="meshes/link2.stl" />
      </geometry>
    </collision>
  </link>
  <joint name="joint2" type="revolute">
    <origin xyz="0 0 0" rpy="-1.5708 3.1416 0" />
    <parent link="link1" />
    <child link="link2" />
    <axis xyz="0 0 1" />
    <limit lower="-2.1" upper="1.57" effort="60" velocity="1.5" />
  </joint>
  <link name="link3">
    <inertial>
      <origin xyz="-0.00033263 -0.0012705 -0.013763" rpy="0 0 0" />
      <mass value="0.29633" />
      <inertia ixx="0.00035616" ixy="3.2634E-06" ixz="1.0656E-06" iyy="0.00035666" iyz="-2.912E-06" izz="0.00016442" />
    </inertial>
    <visual>
      <origin xyz="0 0 0" rpy="0 0 0" />
      <geometry>
        <mesh filename="meshes/link3.stl" />
      </geometry>
      <material name="">
        <color rgba="0.75294 0.75294 0.75294 1" />
      </material>
    </visual>
    <collision>
      <origin xyz="0 0 0" rpy="0 0 0" />
      <geometry>
        <mesh filename="meshes/link3.stl" />
      </geometry>
    </collision>
  </link>
  <joint name="joint3" type="revolute">
    <origin xyz="0 0.3 0" rpy="1.5708 -1.5708 3.1416" />
    <parent link="link2" />
    <child link="link3" />
    <axis xyz="0 0 1" />
    <limit lower="-2.94" upper="2.94" effort="30" velocity="1.5" />
  </joint>
  <link name="link4">
    <inertial>
      <origin xyz="2.1198E-06 0.077687 0.0066608" rpy="0 0 0" />
      <mass value="0.2008" />
      <inertia ixx="0.0001258" ixy="-1.5851E-09" ixz="-3.5207E-09" iyy="0.00010461" iyz="1.7211E-05" izz="0.00012018" />
    </inertial>
    <visual>
      <origin xyz="0 0 0" rpy="0 0 0" />
      <geometry>
        <mesh filename="meshes/link4.stl" />
      </geometry>
      <material name="">
        <color rgba="0.75294 0.75294 0.75294 1" />
      </material>
    </visual>
    <collision>
      <origin xyz="0 0 0" rpy="0 0 0" />
      <geometry>
        <mesh filename="meshes/link4.stl" />
      </geometry>
    </collision>
  </link>
  <joint name="joint4" type="revolute">
    <origin xyz="0 0 0" rpy="1.5708 0 0" />
    <parent link="link3" />
    <child link="link4" />
    <axis xyz="0 0 1" />
    <limit lower="-2.1" upper="2.1" effort="30" velocity="1.5" />
  </joint>
  <link name="link5">
    <inertial>
      <origin xyz="-5.8154E-07 -0.016828 -0.1072" rpy="0 0 0" />
      <mass value="0.30236" />
      <inertia ixx="0.00025776" ixy="-6.7445E-10" ixz="-3.5859E-09" iyy="0.00029228" iyz="3.4788E-06" izz="0.00010798" />
    </inertial>
    <visual>
      <origin xyz="0 0 0" rpy="0 0 0" />
      <geometry>
        <mesh filename="meshes/link5.stl" />
      </geometry>
      <material name="">
        <color rgba="0.75294 0.75294 0.75294 1" />
      </material>
    </visual>
    <collision>
      <origin xyz="0 0 0" rpy="0 0 0" />
      <geometry>
        <mesh filename="meshes/link5.stl" />
      </geometry>
    </collision>
  </link>
  <joint name="joint5" type="revolute">
    <origin xyz="0 0.3125 0" rpy="-1.5708 1.5708 0" />
    <parent link="link4" />
    <child link="link5" />
    <axis xyz="0 0 1" />
    <limit lower="-2.94" upper="2.94" effort="10" velocity="1.5" />
  </joint>
  <link name="link6">
    <inertial>
      <origin xyz="1.6525E-06 -0.00044516 0.0010371" rpy="0 0 0" />
      <mass value="0.14462" />
      <inertia ixx="5.2919E-05" ixy="1.1618E-09" ixz="2.443E-09" iyy="5.7022E-05" iyz="-4.9349E-07" izz="5.2342E-05" />
    </inertial>
    <visual>
      <origin xyz="0 0 0" rpy="0 0 0" />
      <geometry>
        <mesh filename="meshes/link6.stl" />
      </geometry>
      <material name="">
        <color rgba="0.79216 0.81961 0.93333 1" />
      </material>
    </visual>
    <collision>
      <origin xyz="0 0 0" rpy="0 0 0" />
      <geometry>
        <mesh filename="meshes/link6.stl" />
      </geometry>
    </collision>
  </link>
  <joint name="joint6" type="revolute">
    <origin xyz="0 0 0" rpy="1.5708 -1.5708 0" />
    <parent link="link5" />
    <child link="link6" />
    <axis xyz="0 0 1" />
    <limit lower="-1.57" upper="1.57" effort="10" velocity="1.5" />
  </joint>
  <link name="link7">
    <inertial>
      <origin xyz="0.043308 -2.8972E-08 0.018548" rpy="0 0 0" />
      <mass value="0.042354" />
      <inertia ixx="2.5589E-05" ixy="2.0865E-12" ixz="1.2866E-05" iyy="4.7623E-05" iyz="-1.1256E-13" izz="4.3905E-05" />
    </inertial>
    <visual>
      <origin xyz="0 0 0" rpy="0 0 0" />
      <geometry>
        <mesh filename="meshes/link7.stl" />
      </geometry>
      <material name="">
        <color rgba="0.79216 0.81961 0.93333 1" />
      </material>
    </visual>
    <collision>
      <origin xyz="0 0 0" rpy="0 0 0" />
      <geometry>
        <mesh filename="meshes/link7.stl" />
      </geometry>
    </collision>
  </link>
  <joint name="joint7" type="revolute">
    <origin xyz="0 0 0" rpy="1.5708 0 0" />
    <parent link="link6" />
    <child link="link7" />
    <axis xyz="0 0 1" />
    <limit lower="-1.57" upper="0.69" effort="10" velocity="1.5" />
  </joint>
  <link name="end_effector_link" />
  <joint name="end_effector_joint" type="fixed">
    <origin xyz="0.07 0 0" rpy="0 0 0" />
    <parent link="link7" />
    <child link="end_effector_link" />
    <axis xyz="0 0 0" />
  </joint>
</robot>