<?xml version="1.0" encoding="utf-8"?>
<!-- 
#####################################################################################
#
# Copyright (c) 2023-2024 Galbot, Inc. All Rights Reserved.
#
# This software contains confidential and proprietary information of Galbot, Inc.
# ("Confidential Information"). You shall not disclose such Confidential Information
# and shall use it only in accordance with the terms of the license agreement you
# entered into with Galbot, Inc.
#
# UNAUTHORIZED COPYING, USE, OR DISTRIBUTION OF THIS SOFTWARE, OR ANY PORTION OR
# DERIVATIVE THEREOF, IS STRICTLY PROHIBITED. IF YOU HAVE RECEIVED THIS SOFTWARE IN
# ERROR, PLEASE NOTIFY GALBOT, INC. IMMEDIATELY AND DELETE IT FROM YOUR SYSTEM.
#
#####################################################################################
#
# Description: Xacro file for Galbot One left arm
# Author: Yuhao Zeng@Galbot
#
#####################################################################################
-->
<robot name="left_arm" xmlns:xacro="http://www.ros.org/wiki/xacro">

    <!-- Macro -->
    <!-- Inertial matrix -->
    <xacro:macro name="inertial_matrix" params="mass">
        <inertial>
            <mass value="${mass}" />
            <inertia ixx="1.0" ixy="0.0" ixz="0.0" iyy="0.5" iyz="0.0" izz="1.0" />
        </inertial>
    </xacro:macro>
    <xacro:macro name="Box_inertial_matrix" params="m l w h">
        <inertial>
            <mass value="${m}" />
            <inertia ixx="${m*(h*h + l*l)/12}" ixy="0" ixz="0"
                iyy="${m*(w*w + l*l)/12}" iyz="0"
                izz="${m*(w*w + h*h)/12}" />
        </inertial>
    </xacro:macro>

    <!-- links and joints -->
    <xacro:macro name="left_arm" params="parent *origin name:=left_arm">
        <xacro:property name="M_PI" value="3.1415926535897931" />

        <joint name="${name}_joint" type="fixed">
            <xacro:insert_block name="origin" />
            <parent link="${parent}" />
            <child link="${name}_base_link" />
        </joint>

        <link name="${name}_base_link">
            <inertial>
                <origin xyz="-0.00057112 -4.8416E-05 0.048141" rpy="0 0 0" />
                <mass value="0.4009" />
                <inertia
                    ixx="0.00031923"
                    ixy="-3.2026E-07"
                    ixz="-7.8454E-06"
                    iyy="0.00028614"
                    iyz="-6.6497E-07"
                    izz="0.00037028" />
            </inertial>
            <visual>
                <origin xyz="0 0 0" rpy="0 0 0" />
                <geometry>
                    <mesh
                        filename="package://galbot_description/meshes/galbot_one/arm/base_link.stl" />
                </geometry>
                <material name="">
                    <color rgba="0.75294 0.75294 0.75294 1" />
                </material>
            </visual>
            <collision>
                <origin xyz="0 0 0" rpy="0 0 0" />
                <geometry>
                    <mesh
                        filename="package://galbot_description/meshes/galbot_one/arm/base_link.stl" />
                </geometry>
            </collision>
        </link>
        <link name="${name}_link1">
            <inertial>
                <origin xyz="-0.00050997 -0.0011374 -0.0080479" rpy="0 0 0" />
                <mass value="0.41938" />
                <inertia
                    ixx="0.00033493"
                    ixy="7.414E-06"
                    ixz="-1.2269E-06"
                    iyy="0.00037323"
                    iyz="-2.0035E-05"
                    izz="0.00032721" />
            </inertial>
            <visual>
                <origin xyz="0 0 0" rpy="0 0 0" />
                <geometry>
                    <mesh filename="package://galbot_description/meshes/galbot_one/arm/link1.stl" />
                </geometry>
                <material name="">
                    <color rgba="0.75294 0.75294 0.75294 1" />
                </material>
            </visual>
            <collision>
                <origin xyz="0 0 0" rpy="0 0 0" />
                <geometry>
                    <mesh filename="package://galbot_description/meshes/galbot_one/arm/link1.stl" />
                </geometry>
            </collision>
        </link>
        <joint name="${name}_joint1" type="revolute">
            <origin xyz="0 0 0.16" rpy="0 0 1.5708" />
            <parent link="${name}_base_link" />
            <child link="${name}_link1" />
            <axis xyz="0 0 -1" />
            <limit lower="-3.14159265" upper="3.14159265" effort="60" velocity="1.5" />
        </joint>
        <link name="${name}_link2">
            <inertial>
                <origin xyz="0.01039 -0.1292 -0.00045491" rpy="0 0 0" />
                <mass value="0.34989" />
                <inertia
                    ixx="0.00041516"
                    ixy="-4.8591E-05"
                    ixz="2.9375E-07"
                    iyy="0.00023484"
                    iyz="5.2744E-06"
                    izz="0.00041037" />
            </inertial>
            <visual>
                <origin xyz="0 0 0" rpy="0 0 0" />
                <geometry>
                    <mesh filename="package://galbot_description/meshes/galbot_one/arm/link2.stl" />
                </geometry>
                <material name="">
                    <color rgba="0.75294 0.75294 0.75294 1" />
                </material>
            </visual>
            <collision>
                <origin xyz="0 0 0" rpy="0 0 0" />
                <geometry>
                    <mesh filename="package://galbot_description/meshes/galbot_one/arm/link2.stl" />
                </geometry>
            </collision>
        </link>
        <joint name="${name}_joint2" type="revolute">
            <origin xyz="0 0 0" rpy="${M_PI} ${-M_PI/2} ${-M_PI/2}" />
            <parent link="${name}_link1" />
            <child link="${name}_link2" />
            <axis xyz="0 0 1" />
            <limit lower="-1.04719755" upper="3.14159265" effort="60" velocity="1.5" />
        </joint>
        <link name="${name}_link3">
            <inertial>
                <origin xyz="0.00040823 -0.0012004 -0.024826" rpy="0 0 0" />
                <mass value="0.31364" />
                <inertia
                    ixx="0.00061958"
                    ixy="-4.2406E-06"
                    ixz="1.0608E-06"
                    iyy="0.00062065"
                    iyz="5.0156E-06"
                    izz="0.00016934" />
            </inertial>
            <visual>
                <origin xyz="0 0 0" rpy="0 0 0" />
                <geometry>
                    <mesh filename="package://galbot_description/meshes/galbot_one/arm/link3.stl" />
                </geometry>
                <material name="">
                    <color rgba="0.75294 0.75294 0.75294 1" />
                </material>
            </visual>
            <collision>
                <origin xyz="0 0 0" rpy="0 0 0" />
                <geometry>
                    <mesh filename="package://galbot_description/meshes/galbot_one/arm/link3.stl" />
                </geometry>
            </collision>
        </link>
        <joint name="${name}_joint3" type="revolute">
            <origin xyz="0 -0.35 0" rpy="${M_PI/2} -${M_PI/2} 0" />
            <parent link="${name}_link2" />
            <child link="${name}_link3" />
            <axis xyz="0 0 -1" />
            <limit lower="-3.14159265" upper="3.14159265" effort="30" velocity="1.5" />
        </joint>
        <link name="${name}_link4">
            <inertial>
                <origin xyz="-8.3538E-07 -0.081664 -0.0070292" rpy="0 0 0" />
                <mass value="0.20322" />
                <inertia
                    ixx="0.0001327"
                    ixy="-5.358E-10"
                    ixz="-3.6629E-09"
                    iyy="0.00010565"
                    iyz="1.8727E-05"
                    izz="0.00012742" />
            </inertial>
            <visual>
                <origin xyz="0 0 0" rpy="0 0 0" />
                <geometry>
                    <mesh filename="package://galbot_description/meshes/galbot_one/arm/link4.stl" />
                </geometry>
                <material name="">
                    <color rgba="0.75294 0.75294 0.75294 1" />
                </material>
            </visual>
            <collision>
                <origin xyz="0 0 0" rpy="0 0 0" />
                <geometry>
                    <mesh filename="package://galbot_description/meshes/galbot_one/arm/link4.stl" />
                </geometry>
            </collision>
        </link>
        <joint name="${name}_joint4" type="revolute">
            <origin xyz="0 0 0" rpy="-1.5708 0 0" />
            <parent link="${name}_link3" />
            <child link="${name}_link4" />
            <axis xyz="0 0 1" />
            <limit lower="-2.26892803" upper="2.26892803" effort="30" velocity="1.5" />
        </joint>
        <link name="${name}_link5">
            <inertial>
                <origin xyz="2.6642E-06 -0.0017508 -0.0075128" rpy="0 0 0" />
                <mass value="0.16212" />
                <inertia
                    ixx="9.277E-05"
                    ixy="-3.0565E-09"
                    ixz="6.2958E-10"
                    iyy="8.7403E-05"
                    iyz="2.6612E-06"
                    izz="7.2409E-05" />
            </inertial>
            <visual>
                <origin xyz="0 0 0" rpy="0 0 0" />
                <geometry>
                    <mesh filename="package://galbot_description/meshes/galbot_one/arm/link5.stl" />
                </geometry>
                <material name="">
                    <color rgba="0.75294 0.75294 0.75294 1" />
                </material>
            </visual>
            <collision>
                <origin xyz="0 0 0" rpy="0 0 0" />
                <geometry>
                    <mesh filename="package://galbot_description/meshes/galbot_one/arm/link5.stl" />
                </geometry>
            </collision>
        </link>
        <joint name="${name}_joint5" type="revolute">
            <origin xyz="0 -0.205 0" rpy="1.5708 0 0" />
            <parent link="${name}_link4" />
            <child link="${name}_link5" />
            <axis xyz="0 0 -1" />
            <limit lower="-3.14159265" upper="3.14159265" effort="10" velocity="1.5" />
        </joint>
        <link name="${name}_link6">
            <inertial>
                <origin xyz="-0.00010941 -0.058252 -0.001489" rpy="0 0 0" />
                <mass value="0.15944" />
                <inertia
                    ixx="9.2919E-05"
                    ixy="2.4883E-07"
                    ixz="-1.2429E-07"
                    iyy="6.6749E-05"
                    iyz="6.9276E-06"
                    izz="9.0432E-05" />
            </inertial>
            <visual>
                <origin xyz="0 0 0" rpy="0 0 0" />
                <geometry>
                    <mesh filename="package://galbot_description/meshes/galbot_one/arm/link6.stl" />
                </geometry>
                <material name="">
                    <color rgba="0.75294 0.75294 0.75294 1" />
                </material>
            </visual>
            <collision>
                <origin xyz="0 0 0" rpy="0 0 0" />
                <geometry>
                    <mesh filename="package://galbot_description/meshes/galbot_one/arm/link6.stl" />
                </geometry>
            </collision>
        </link>
        <joint name="${name}_joint6" type="revolute">
            <origin xyz="0 0.0475 0.0475" rpy="-0.7854 0 0" />
            <parent link="${name}_link5" />
            <child link="${name}_link6" />
            <axis xyz="0 0 1" />
            <limit lower="-1.04719755" upper="1.57079633" effort="10" velocity="1.5" />
        </joint>
        <link name="${name}_link7">
            <inertial>
                <origin xyz="4.2409E-08 -0.013157 -0.031651" rpy="0 0 0" />
                <mass value="0.17741" />
                <inertia
                    ixx="0.0001273"
                    ixy="-2.2846E-10"
                    ixz="-5.306E-11"
                    iyy="0.00011627"
                    iyz="-3.7825E-05"
                    izz="0.00012079" />
            </inertial>
            <visual>
                <origin xyz="0 0 0" rpy="0 0 0" />
                <geometry>
                    <mesh filename="package://galbot_description/meshes/galbot_one/arm/link7.stl" />
                </geometry>
                <material name="">
                    <color rgba="0.79216 0.81961 0.93333 1" />
                </material>
            </visual>
            <collision>
                <origin xyz="0 0 0" rpy="0 0 0" />
                <geometry>
                    <mesh filename="package://galbot_description/meshes/galbot_one/arm/link7.stl" />
                </geometry>
            </collision>
        </link>
        <joint name="${name}_joint7" type="revolute">
            <origin xyz="0 -0.099175 0" rpy="${M_PI/2} 0 0" />
            <parent link="${name}_link6" />
            <child link="${name}_link7" />
            <axis xyz="0 0 1" />
            <limit lower="-0.78539816" upper="1.57079633" effort="10" velocity="1.5" />
        </joint>

        <link name="${name}_end_effector_mount_link"></link>
        <joint name="${name}_end_effector_mount_joint" type="fixed">
            <origin xyz="0 0.056569 0.024569" rpy="${M_PI/4} 0 0" />
            <parent link="${name}_link7" />
            <child link="${name}_end_effector_mount_link" />
            <axis xyz="0 0 1" />
        </joint>

    </xacro:macro>

</robot>